<?xml version="1.0" encoding="utf-8"?>
<!-- This URDF was automatically created by SolidWorks to URDF Exporter! Originally created by Stephen Brawner (brawner@gmail.com) 
     Commit Version: 1.6.0-4-g7f85cfe  Build Version: 1.6.7995.38578
     For more information, please see http://wiki.ros.org/sw_urdf_exporter -->
<robot
  name="urdfv5">
  <link
    name="base_link">
    <inertial>
      <origin
        xyz="-0.0435393633147197 1.22538169029518E-05 0.0288009133501952"
        rpy="0 0 0" />
      <mass
        value="1.80445503924572" />
      <inertia
        ixx="0.00557261131322256"
        ixy="1.30566290520113E-06"
        ixz="-0.0005394752363291"
        iyy="0.0133501948737187"
        iyz="4.5057300847886E-07"
        izz="0.0165394809238565" />
    </inertial>
    <visual>
      <origin
        xyz="0 0 0"
        rpy="0 0 0" />
      <geometry>
        <mesh
          filename="package://urdfv5/meshes/base_link.STL" />
      </geometry>
      <material
        name="">
        <color
          rgba="0.792156862745098 0.819607843137255 0.933333333333333 1" />
      </material>
    </visual>
    <collision>
      <origin
        xyz="0 0 0"
        rpy="0 0 0" />
      <geometry>
        <mesh
          filename="package://urdfv5/meshes/base_link.STL" />
      </geometry>
    </collision>
  </link>
  <link
    name="base">
    <inertial>
      <origin
        xyz="-3.642206133736E-05 -0.0118679007139265 0.0827015228083971"
        rpy="0 0 0" />
      <mass
        value="2.09089475872426" />
      <inertia
        ixx="0.0136133851140564"
        ixy="4.81729455017446E-06"
        ixz="-8.59098005598292E-06"
        iyy="0.00966544956416382"
        iyz="-0.000408881345999402"
        izz="0.00889732541662392" />
    </inertial>
    <visual>
      <origin
        xyz="0 0 0"
        rpy="0 0 0" />
      <geometry>
        <mesh
          filename="package://urdfv5/meshes/base.STL" />
      </geometry>
      <material
        name="">
        <color
          rgba="0.792156862745098 0.819607843137255 0.933333333333333 1" />
      </material>
    </visual>
    <collision>
      <origin
        xyz="0 0 0"
        rpy="0 0 0" />
      <geometry>
        <mesh
          filename="package://urdfv5/meshes/base.STL" />
      </geometry>
    </collision>
  </link>
  <joint
    name="joint_1"
    type="continuous">
    <origin
      xyz="0 0 0.0805626889741612"
      rpy="0 0 -0.0137749399473416" />
    <parent
      link="base_link" />
    <child
      link="base" />
    <axis
      xyz="0 0 1" />
  </joint>
  <link
    name="shoulder">
    <inertial>
      <origin
        xyz="0.000114821633251605 0.00164617005672685 0.079941299505606"
        rpy="0 0 0" />
      <mass
        value="1.9311302244136" />
      <inertia
        ixx="0.0170861143600446"
        ixy="3.41444124886214E-06"
        ixz="-5.13579918498232E-07"
        iyy="0.0162696160792994"
        iyz="-0.000123088013545127"
        izz="0.00359987375721594" />
    </inertial>
    <visual>
      <origin
        xyz="0 0 0"
        rpy="0 0 0" />
      <geometry>
        <mesh
          filename="package://urdfv5/meshes/shoulder.STL" />
      </geometry>
      <material
        name="">
        <color
          rgba="0.792156862745098 0.819607843137255 0.933333333333333 1" />
      </material>
    </visual>
    <collision>
      <origin
        xyz="0 0 0"
        rpy="0 0 0" />
      <geometry>
        <mesh
          filename="package://urdfv5/meshes/shoulder.STL" />
      </geometry>
    </collision>
  </link>
  <joint
    name="joint_2"
    type="continuous">
    <origin
      xyz="0 0 0.166937311025839"
      rpy="0 -0.0401786148125149 0" />
    <parent
      link="base" />
    <child
      link="shoulder" />
    <axis
      xyz="0 1 0" />
  </joint>
  <link
    name="elbow">
    <inertial>
      <origin
        xyz="-7.46045453986488E-05 -0.000200828897961525 0.0430510848285705"
        rpy="0 0 0" />
      <mass
        value="0.777952518165522" />
      <inertia
        ixx="0.00228138046770406"
        ixy="6.74965200477039E-08"
        ixz="-6.02495655393824E-07"
        iyy="0.00230093015725966"
        iyz="-3.06257161230913E-05"
        izz="0.000730693959243023" />
    </inertial>
    <visual>
      <origin
        xyz="0 0 0"
        rpy="0 0 0" />
      <geometry>
        <mesh
          filename="package://urdfv5/meshes/elbow.STL" />
      </geometry>
      <material
        name="">
        <color
          rgba="0.792156862745098 0.819607843137255 0.933333333333333 1" />
      </material>
    </visual>
    <collision>
      <origin
        xyz="0 0 0"
        rpy="0 0 0" />
      <geometry>
        <mesh
          filename="package://urdfv5/meshes/elbow.STL" />
      </geometry>
    </collision>
  </link>
  <joint
    name="joint_3"
    type="continuous">
    <origin
      xyz="0 0 0.221123792803564"
      rpy="0 0.0401786148125149 0" />
    <parent
      link="shoulder" />
    <child
      link="elbow" />
    <axis
      xyz="0 1 0" />
  </joint>
  <link
    name="wrist_1">
    <inertial>
      <origin
        xyz="0.000153325816812655 0.0025437716284466 0.0552077428933772"
        rpy="0 0 0" />
      <mass
        value="0.336033431090024" />
      <inertia
        ixx="0.00069858897414835"
        ixy="-1.06885826113012E-06"
        ixz="4.79930621864448E-06"
        iyy="0.000573509858053779"
        iyz="1.12101684178498E-05"
        izz="0.000348806651356732" />
    </inertial>
    <visual>
      <origin
        xyz="0 0 0"
        rpy="0 0 0" />
      <geometry>
        <mesh
          filename="package://urdfv5/meshes/wrist_1.STL" />
      </geometry>
      <material
        name="">
        <color
          rgba="0.792156862745098 0.819607843137255 0.933333333333333 1" />
      </material>
    </visual>
    <collision>
      <origin
        xyz="0 0 0"
        rpy="0 0 0" />
      <geometry>
        <mesh
          filename="package://urdfv5/meshes/wrist_1.STL" />
      </geometry>
    </collision>
  </link>
  <joint
    name="joint_4"
    type="continuous">
    <origin
      xyz="0 0.000500999999999752 0.129539254362443"
      rpy="0 0 0" />
    <parent
      link="elbow" />
    <child
      link="wrist_1" />
    <axis
      xyz="0 0 1" />
  </joint>
  <link
    name="wrist_2">
    <inertial>
      <origin
        xyz="1.77688284443978E-05 0.000385812686423792 0.00382819956222746"
        rpy="0 0 0" />
      <mass
        value="0.158623990907744" />
      <inertia
        ixx="8.93595780141302E-05"
        ixy="-2.61043353678291E-09"
        ixz="-6.69999126984601E-08"
        iyy="0.000106318526071324"
        iyz="-6.1988141359002E-07"
        izz="7.50977321539318E-05" />
    </inertial>
    <visual>
      <origin
        xyz="0 0 0"
        rpy="0 0 0" />
      <geometry>
        <mesh
          filename="package://urdfv5/meshes/wrist_2.STL" />
      </geometry>
      <material
        name="">
        <color
          rgba="0.792156862745098 0.819607843137255 0.933333333333333 1" />
      </material>
    </visual>
    <collision>
      <origin
        xyz="0 0 0"
        rpy="0 0 0" />
      <geometry>
        <mesh
          filename="package://urdfv5/meshes/wrist_2.STL" />
      </geometry>
    </collision>
  </link>
  <joint
    name="joint_5"
    type="continuous">
    <origin
      xyz="0 0 0.098960745637557"
      rpy="0 0 0" />
    <parent
      link="wrist_1" />
    <child
      link="wrist_2" />
    <axis
      xyz="0 1 0" />
  </joint>
  <link
    name="gripper_base">
    <inertial>
      <origin
        xyz="0.0143867707676764 -0.00449126467228944 0.734040602378814"
        rpy="0 0 0" />
      <mass
        value="0.0669550612665462" />
      <inertia
        ixx="2.24885103666953E-05"
        ixy="2.35779531665101E-06"
        ixz="-2.87441655039097E-06"
        iyy="3.18452563755661E-05"
        iyz="3.57683862208844E-07"
        izz="3.67649414256568E-05" />
    </inertial>
    <visual>
      <origin
        xyz="0 0 0"
        rpy="0 0 0" />
      <geometry>
        <mesh
          filename="package://urdfv5/meshes/gripper_base.STL" />
      </geometry>
      <material
        name="">
        <color
          rgba="0.792156862745098 0.819607843137255 0.933333333333333 1" />
      </material>
    </visual>
    <collision>
      <origin
        xyz="0 0 0"
        rpy="0 0 0" />
      <geometry>
        <mesh
          filename="package://urdfv5/meshes/gripper_base.STL" />
      </geometry>
    </collision>
  </link>
  <joint
    name="joint_6"
    type="fixed">
    <origin
      xyz="0.00101787720548718 0.0025808298232558 -0.67198995308091"
      rpy="0 0 0" />
    <parent
      link="wrist_2" />
    <child
      link="gripper_base" />
    <axis
      xyz="0 0 0" />
  </joint>
  <link
    name="gripper_link_gear1">
    <inertial>
      <origin
        xyz="-0.00297505714593504 -0.000951058332112287 0.00793987065824242"
        rpy="0 0 0" />
      <mass
        value="0.0043827321176342" />
      <inertia
        ixx="9.89267955956112E-07"
        ixy="-2.40994167790054E-09"
        ixz="-4.25781888054711E-09"
        iyy="8.26887819478162E-07"
        iyz="-3.67425672143889E-08"
        izz="1.88326002162975E-07" />
    </inertial>
    <visual>
      <origin
        xyz="0 0 0"
        rpy="0 0 0" />
      <geometry>
        <mesh
          filename="package://urdfv5/meshes/gripper_link_gear1.STL" />
      </geometry>
      <material
        name="">
        <color
          rgba="0.792156862745098 0.819607843137255 0.933333333333333 1" />
      </material>
    </visual>
    <collision>
      <origin
        xyz="0 0 0"
        rpy="0 0 0" />
      <geometry>
        <mesh
          filename="package://urdfv5/meshes/gripper_link_gear1.STL" />
      </geometry>
    </collision>
  </link>
  <joint
    name="joint_7"
    type="continuous">
    <origin
      xyz="0.0022853 -0.016581 0.73698"
      rpy="0 0 0.013775" />
    <parent
      link="gripper_base" />
    <child
      link="gripper_link_gear1" />
    <axis
      xyz="0.99989 -0.013774 -0.0046829" />
  </joint>
  <link
    name="gripper_link_gear2">
    <inertial>
      <origin
        xyz="0.00299446841718953 -0.00793429080604857 -0.000936572435455252"
        rpy="0 0 0" />
      <mass
        value="0.00438273213416302" />
      <inertia
        ixx="9.89317570900061E-07"
        ixy="1.98696293022724E-10"
        ixz="-7.64266699711604E-10"
        iyy="1.89001473415262E-07"
        iyz="4.23806388608005E-08"
        izz="8.2616283422686E-07" />
    </inertial>
    <visual>
      <origin
        xyz="0 0 0"
        rpy="0 0 0" />
      <geometry>
        <mesh
          filename="package://urdfv5/meshes/gripper_link_gear2.STL" />
      </geometry>
      <material
        name="">
        <color
          rgba="0.792156862745098 0.819607843137255 0.933333333333333 1" />
      </material>
    </visual>
    <collision>
      <origin
        xyz="0 0 0"
        rpy="0 0 0" />
      <geometry>
        <mesh
          filename="package://urdfv5/meshes/gripper_link_gear2.STL" />
      </geometry>
    </collision>
  </link>
  <joint
    name="joint_8"
    type="continuous">
    <origin
      xyz="0.0022853 0.011419 0.73698"
      rpy="-1.5621 -0.0047239 -3.1369" />
    <parent
      link="gripper_base" />
    <child
      link="gripper_link_gear2" />
    <axis
      xyz="0.99999 0 -0.0046829" />
    <mimic
      joint=""
      multiplier="-1"
      offset="1.57" />
  </joint>
  <link
    name="gripper_arm1">
    <inertial>
      <origin
        xyz="-0.0030138820723864 -0.0200002768409102 1.41270823689754E-05"
        rpy="0 0 0" />
      <mass
        value="0.00163735500294603" />
      <inertia
        ixx="3.04623057395779E-07"
        ixy="3.1959275327615E-14"
        ixz="-4.21698270677683E-12"
        iyy="1.02986323316765E-08"
        iyz="4.46309318162813E-13"
        izz="3.03722580975889E-07" />
    </inertial>
    <visual>
      <origin
        xyz="0 0 0"
        rpy="0 0 0" />
      <geometry>
        <mesh
          filename="package://urdfv5/meshes/gripper_arm1.STL" />
      </geometry>
      <material
        name="">
        <color
          rgba="0.792156862745098 0.819607843137255 0.933333333333333 1" />
      </material>
    </visual>
    <collision>
      <origin
        xyz="0 0 0"
        rpy="0 0 0" />
      <geometry>
        <mesh
          filename="package://urdfv5/meshes/gripper_arm1.STL" />
      </geometry>
    </collision>
  </link>
  <joint
    name="joint_9"
    type="continuous">
    <origin
      xyz="0.002394 -0.0095808 0.75697"
      rpy="-1.562 0.0046418 0.0046828" />
    <parent
      link="gripper_base" />
    <child
      link="gripper_arm1" />
    <axis
      xyz="0.99999 0 -0.0046829" />
    <mimic
      joint="joint_7"
      multiplier="1"
      offset="0" />
  </joint>
  <link
    name="gripper_arm2">
    <inertial>
      <origin
        xyz="-0.00305619055725292 0.0200000108825259 1.43009533843941E-05"
        rpy="0 0 0" />
      <mass
        value="0.00163735500294604" />
      <inertia
        ixx="3.0462305739579E-07"
        ixy="-2.77675152125617E-14"
        ixz="-4.21698270674388E-12"
        iyy="1.02986323316827E-08"
        iyz="4.48804886261591E-13"
        izz="3.03722580975893E-07" />
    </inertial>
    <visual>
      <origin
        xyz="0 0 0"
        rpy="0 0 0" />
      <geometry>
        <mesh
          filename="package://urdfv5/meshes/gripper_arm2.STL" />
      </geometry>
      <material
        name="">
        <color
          rgba="0.792156862745098 0.819607843137255 0.933333333333333 1" />
      </material>
    </visual>
    <collision>
      <origin
        xyz="0 0 0"
        rpy="0 0 0" />
      <geometry>
        <mesh
          filename="package://urdfv5/meshes/gripper_arm2.STL" />
      </geometry>
    </collision>
  </link>
  <joint
    name="joint_10"
    type="continuous">
    <origin
      xyz="0.0024363 0.0044192 0.75697"
      rpy="1.562 0.0046419 -0.0046828" />
    <parent
      link="gripper_base" />
    <child
      link="gripper_arm2" />
    <axis
      xyz="0.99999 0 -0.0046829" />
    <mimic
      joint="joint_9"
      multiplier="-1"
      offset="0" />
  </joint>
</robot>