<?xml version="1.0" encoding="utf-8"?>
<!-- This URDF was automatically created by SolidWorks to URDF Exporter! Originally created by Stephen Brawner (brawner@gmail.com) 
     Commit Version: 1.6.0-4-g7f85cfe  Build Version: 1.6.7995.38578
     For more information, please see http://wiki.ros.org/sw_urdf_exporter -->
<robot
  name="moveo_urdf4">
  <link
    name="base_link">
    <inertial>
      <origin
        xyz="-0.0435393633147197 1.22538169029518E-05 0.0288009133501952"
        rpy="0 0 0" />
      <mass
        value="1.80445503924572" />
      <inertia
        ixx="0.00557261131322256"
        ixy="1.30566290520133E-06"
        ixz="-0.000539475236329099"
        iyy="0.0133501948737187"
        iyz="4.50573008478811E-07"
        izz="0.0165394809238565" />
    </inertial>
    <visual>
      <origin
        xyz="0 0 0"
        rpy="0 0 0" />
      <geometry>
        <mesh
          filename="package://moveo_urdf4/meshes/base_link.STL" />
      </geometry>
      <material
        name="">
        <color
          rgba="0.792156862745098 0.819607843137255 0.933333333333333 1" />
      </material>
    </visual>
    <collision>
      <origin
        xyz="0 0 0"
        rpy="0 0 0" />
      <geometry>
        <mesh
          filename="package://moveo_urdf4/meshes/base_link.STL" />
      </geometry>
    </collision>
  </link>
  <link
    name="base">
    <inertial>
      <origin
        xyz="-3.6422061337249E-05 -0.0118679007139265 0.082701522808397"
        rpy="0 0 0" />
      <mass
        value="2.09089475872426" />
      <inertia
        ixx="0.0136133851140564"
        ixy="4.81729455017446E-06"
        ixz="-8.59098005598298E-06"
        iyy="0.00966544956416382"
        iyz="-0.000408881345999401"
        izz="0.00889732541662392" />
    </inertial>
    <visual>
      <origin
        xyz="0 0 0"
        rpy="0 0 0" />
      <geometry>
        <mesh
          filename="package://moveo_urdf4/meshes/base.STL" />
      </geometry>
      <material
        name="">
        <color
          rgba="0.792156862745098 0.819607843137255 0.933333333333333 1" />
      </material>
    </visual>
    <collision>
      <origin
        xyz="0 0 0"
        rpy="0 0 0" />
      <geometry>
        <mesh
          filename="package://moveo_urdf4/meshes/base.STL" />
      </geometry>
    </collision>
  </link>
  <joint
    name="joint_1"
    type="continuous">
    <origin
      xyz="0 0 0.0805626889741612"
      rpy="0 0 -0.0137749399473416" />
    <parent
      link="base_link" />
    <child
      link="base" />
    <axis
      xyz="0 0 1" />
  </joint>
  <link
    name="shoulder">
    <inertial>
      <origin
        xyz="0.000114827478712443 0.00164617006281503 0.0799412994935286"
        rpy="0 0 0" />
      <mass
        value="1.93113022438464" />
      <inertia
        ixx="0.017086114358631"
        ixy="3.41443254346321E-06"
        ixz="-5.1456620742978E-07"
        iyy="0.0162696160784253"
        iyz="-0.000123088014654492"
        izz="0.00359987375688094" />
    </inertial>
    <visual>
      <origin
        xyz="0 0 0"
        rpy="0 0 0" />
      <geometry>
        <mesh
          filename="package://moveo_urdf4/meshes/shoulder.STL" />
      </geometry>
      <material
        name="">
        <color
          rgba="0.792156862745098 0.819607843137255 0.933333333333333 1" />
      </material>
    </visual>
    <collision>
      <origin
        xyz="0 0 0"
        rpy="0 0 0" />
      <geometry>
        <mesh
          filename="package://moveo_urdf4/meshes/shoulder.STL" />
      </geometry>
    </collision>
  </link>
  <joint
    name="joint_2"
    type="continuous">
    <origin
      xyz="0 0 0.166937311025839"
      rpy="0 -0.0401786148125149 0" />
    <parent
      link="base" />
    <child
      link="shoulder" />
    <axis
      xyz="0 1 0" />
  </joint>
  <link
    name="elbow">
    <inertial>
      <origin
        xyz="-7.45883861681396E-05 -0.000200828912791273 0.0430510855034872"
        rpy="0 0 0" />
      <mass
        value="0.777952518470333" />
      <inertia
        ixx="0.00228138046948802"
        ixy="6.74966748087955E-08"
        ixz="-6.02495823710711E-07"
        iyy="0.00230093015854768"
        iyz="-3.06257153292043E-05"
        izz="0.000730693959609596" />
    </inertial>
    <visual>
      <origin
        xyz="0 0 0"
        rpy="0 0 0" />
      <geometry>
        <mesh
          filename="package://moveo_urdf4/meshes/elbow.STL" />
      </geometry>
      <material
        name="">
        <color
          rgba="0.792156862745098 0.819607843137255 0.933333333333333 1" />
      </material>
    </visual>
    <collision>
      <origin
        xyz="0 0 0"
        rpy="0 0 0" />
      <geometry>
        <mesh
          filename="package://moveo_urdf4/meshes/elbow.STL" />
      </geometry>
    </collision>
  </link>
  <joint
    name="joint_3"
    type="continuous">
    <origin
      xyz="0 0 0.221123792803564"
      rpy="0 0.0401786148125149 0" />
    <parent
      link="shoulder" />
    <child
      link="elbow" />
    <axis
      xyz="0 1 0" />
  </joint>
  <link
    name="wrist_1">
    <inertial>
      <origin
        xyz="0.00015334197288952 0.00254377162843955 0.0552077435428409"
        rpy="0 0 0" />
      <mass
        value="0.336033431090233" />
      <inertia
        ixx="0.000698588974148824"
        ixy="-1.06885826099814E-06"
        ixz="4.79930621867251E-06"
        iyy="0.000573509858054147"
        iyz="1.12101684178369E-05"
        izz="0.00034880665135697" />
    </inertial>
    <visual>
      <origin
        xyz="0 0 0"
        rpy="0 0 0" />
      <geometry>
        <mesh
          filename="package://moveo_urdf4/meshes/wrist_1.STL" />
      </geometry>
      <material
        name="">
        <color
          rgba="0.792156862745098 0.819607843137255 0.933333333333333 1" />
      </material>
    </visual>
    <collision>
      <origin
        xyz="0 0 0"
        rpy="0 0 0" />
      <geometry>
        <mesh
          filename="package://moveo_urdf4/meshes/wrist_1.STL" />
      </geometry>
    </collision>
  </link>
  <joint
    name="joint_4"
    type="continuous">
    <origin
      xyz="0 0.000500999999999752 0.129539254362443"
      rpy="0 0 0" />
    <parent
      link="elbow" />
    <child
      link="wrist_1" />
    <axis
      xyz="0 0 1" />
  </joint>
  <link
    name="wrist_2">
    <inertial>
      <origin
        xyz="1.77849845188205E-05 0.000385812686423626 0.00382820021170582"
        rpy="0 0 0" />
      <mass
        value="0.158623990907743" />
      <inertia
        ixx="8.93595780141303E-05"
        ixy="-2.61043353672267E-09"
        ixz="-6.69999126986908E-08"
        iyy="0.000106318526071323"
        iyz="-6.19881413590131E-07"
        izz="7.50977321539299E-05" />
    </inertial>
    <visual>
      <origin
        xyz="0 0 0"
        rpy="0 0 0" />
      <geometry>
        <mesh
          filename="package://moveo_urdf4/meshes/wrist_2.STL" />
      </geometry>
      <material
        name="">
        <color
          rgba="0.792156862745098 0.819607843137255 0.933333333333333 1" />
      </material>
    </visual>
    <collision>
      <origin
        xyz="0 0 0"
        rpy="0 0 0" />
      <geometry>
        <mesh
          filename="package://moveo_urdf4/meshes/wrist_2.STL" />
      </geometry>
    </collision>
  </link>
  <joint
    name="joint_5"
    type="continuous">
    <origin
      xyz="0 0 0.098960745637557"
      rpy="0 0 0" />
    <parent
      link="wrist_1" />
    <child
      link="wrist_2" />
    <axis
      xyz="0 1 0" />
  </joint>
  <link
    name="gripper_base">
    <inertial>
      <origin
        xyz="0.0143867911822684 -0.00449126467044625 0.734040603199584"
        rpy="0 0 0" />
      <mass
        value="0.0669550612594658" />
      <inertia
        ixx="2.24885103643744E-05"
        ixy="2.35779531725574E-06"
        ixz="-2.87441655035395E-06"
        iyy="3.18452563753843E-05"
        iyz="3.57683862329468E-07"
        izz="3.67649414231891E-05" />
    </inertial>
    <visual>
      <origin
        xyz="0 0 0"
        rpy="0 0 0" />
      <geometry>
        <mesh
          filename="package://moveo_urdf4/meshes/gripper_base.STL" />
      </geometry>
      <material
        name="">
        <color
          rgba="0.792156862745098 0.819607843137255 0.933333333333333 1" />
      </material>
    </visual>
    <collision>
      <origin
        xyz="0 0 0"
        rpy="0 0 0" />
      <geometry>
        <mesh
          filename="package://moveo_urdf4/meshes/gripper_base.STL" />
      </geometry>
    </collision>
  </link>
  <joint
    name="joint_6"
    type="fixed">
    <origin
      xyz="0.00101787720548718 0.0025808298232558 -0.67198995308091"
      rpy="0 0 0" />
    <parent
      link="wrist_2" />
    <child
      link="gripper_base" />
    <axis
      xyz="0 0 0" />
  </joint>
  <link
    name="gripper_link_gear">
    <inertial>
      <origin
        xyz="-0.00276852355417923 0.0140394742220412 0.00793986618178577"
        rpy="0 0 0" />
      <mass
        value="0.00876546425065962" />
      <inertia
        ixx="1.97854546134519E-06"
        ixy="-4.47535518620428E-09"
        ixz="-7.501404002951E-09"
        iyy="1.65376694829978E-06"
        iyz="1.02217561646176E-10"
        izz="3.76651246395816E-07" />
    </inertial>
    <visual>
      <origin
        xyz="0 0 0"
        rpy="0 0 0" />
      <geometry>
        <mesh
          filename="package://moveo_urdf4/meshes/gripper_link_gear.STL" />
      </geometry>
      <material
        name="">
        <color
          rgba="0.792156862745098 0.819607843137255 0.933333333333333 1" />
      </material>
    </visual>
    <collision>
      <origin
        xyz="0 0 0"
        rpy="0 0 0" />
      <geometry>
        <mesh
          filename="package://moveo_urdf4/meshes/gripper_link_gear.STL" />
      </geometry>
    </collision>
  </link>
  <joint
    name="joint_7"
    type="continuous">
    <origin
      xyz="0.0022853 -0.016581 0.73698"
      rpy="0 0 0.013775" />
    <parent
      link="gripper_base" />
    <child
      link="gripper_link_gear" />
    <axis
      xyz="0.99989 -0.013774 -0.0046829" />
  </joint>
  <link
    name="gripper_lin_arm">
    <inertial>
      <origin
        xyz="-0.00315153381206024 -0.00695851964164751 0.0199989358517276"
        rpy="0 0 0" />
      <mass
        value="0.00327471000589204" />
      <inertia
        ixx="6.09245803091741E-07"
        ixy="-2.54242561812789E-11"
        ixz="-2.35149476765821E-11"
        iyy="6.07400452046017E-07"
        iyz="3.70097121441051E-11"
        izz="2.06422862689512E-08" />
    </inertial>
    <visual>
      <origin
        xyz="0 0 0"
        rpy="0 0 0" />
      <geometry>
        <mesh
          filename="package://moveo_urdf4/meshes/gripper_lin_arm.STL" />
      </geometry>
      <material
        name="">
        <color
          rgba="0.792156862745098 0.819607843137255 0.933333333333333 1" />
      </material>
    </visual>
    <collision>
      <origin
        xyz="0 0 0"
        rpy="0 0 0" />
      <geometry>
        <mesh
          filename="package://moveo_urdf4/meshes/gripper_lin_arm.STL" />
      </geometry>
    </collision>
  </link>
  <joint
    name="joint_8"
    type="continuous">
    <origin
      xyz="0.0024363 0.0044192 0.75697"
      rpy="0 0.0046426 0.013775" />
    <parent
      link="gripper_base" />
    <child
      link="gripper_lin_arm" />
    <axis
      xyz="0.99991 -0.013774 -4.0711E-05" />
    <mimic
      joint="joint_7"
      multiplier="1"
      offset="0" />
  </joint>
</robot>