<?xml version="1.0" encoding="utf-8"?>
<!-- This URDF was automatically created by SolidWorks to URDF Exporter! Originally created by Stephen Brawner (brawner@gmail.com) 
     Commit Version: 1.6.0-4-g7f85cfe  Build Version: 1.6.7995.38578
     For more information, please see http://wiki.ros.org/sw_urdf_exporter -->
<robot
  name="urdf_v10">
  <link
    name="base">
    <inertial>
      <origin
        xyz="-0.0277896697300234 0.023407682473858 0.0288009133496202"
        rpy="0 0 0" />
      <mass
        value="1.80445503906846" />
      <inertia
        ixx="0.00557261131275037"
        ixy="1.30566247737982E-06"
        ixz="-0.000539475235901591"
        iyy="0.0133501948734043"
        iyz="4.50573059784861E-07"
        izz="0.0165394809237048" />
    </inertial>
    <visual>
      <origin
        xyz="0 0 0"
        rpy="0 0 0" />
      <geometry>
        <mesh
          filename="package://urdf_v10/meshes/base.STL" />
      </geometry>
      <material
        name="">
        <color
          rgba="0.792156862745098 0.819607843137255 0.933333333333333 1" />
      </material>
    </visual>
    <collision>
      <origin
        xyz="0 0 0"
        rpy="0 0 0" />
      <geometry>
        <mesh
          filename="package://urdf_v10/meshes/base.STL" />
      </geometry>
    </collision>
  </link>
  <link
    name="base_link ">
    <inertial>
      <origin
        xyz="0.0157132867710386 0.0115275527781497 0.181315186078074"
        rpy="0 0 0" />
      <mass
        value="2.09089508032483" />
      <inertia
        ixx="0.0136133861664862"
        ixy="4.81773478827695E-06"
        ixz="-8.58975681070907E-06"
        iyy="0.00966545437107039"
        iyz="-0.000408881289480716"
        izz="0.00889732683613491" />
    </inertial>
    <visual>
      <origin
        xyz="0 0 0"
        rpy="0 0 0" />
      <geometry>
        <mesh
          filename="package://urdf_v10/meshes/base_link .STL" />
      </geometry>
      <material
        name="">
        <color
          rgba="0.792156862745098 0.819607843137255 0.933333333333333 1" />
      </material>
    </visual>
    <collision>
      <origin
        xyz="0 0 0"
        rpy="0 0 0" />
      <geometry>
        <mesh
          filename="package://urdf_v10/meshes/base_link .STL" />
      </geometry>
    </collision>
  </link>
  <joint
    name="joint_1"
    type="continuous">
    <origin
      xyz="0 0 -0.0180509631759313"
      rpy="0 0 0" />
    <parent
      link="base" />
    <child
      link="base_link " />
    <axis
      xyz="0 0 1" />
  </joint>
  <link
    name="shoulder">
    <inertial>
      <origin
        xyz="0.0158644325848684 0.025041628375034 0.178555309070935"
        rpy="0 0 0" />
      <mass
        value="1.93113192655753" />
      <inertia
        ixx="0.0170862699557534"
        ixy="3.41462460165439E-06"
        ixz="-5.32111655341239E-07"
        iyy="0.0162697572723934"
        iyz="-0.000123096765635521"
        izz="0.00359988405516652" />
    </inertial>
    <visual>
      <origin
        xyz="0 0 0"
        rpy="0 0 0" />
      <geometry>
        <mesh
          filename="package://urdf_v10/meshes/shoulder.STL" />
      </geometry>
      <material
        name="">
        <color
          rgba="0.792156862745098 0.819607843137255 0.933333333333333 1" />
      </material>
    </visual>
    <collision>
      <origin
        xyz="0 0 0"
        rpy="0 0 0" />
      <geometry>
        <mesh
          filename="package://urdf_v10/meshes/shoulder.STL" />
      </geometry>
    </collision>
  </link>
  <joint
    name="joint_2"
    type="continuous">
    <origin
      xyz="0 0 0.166937311025839"
      rpy="0 0 0" />
    <parent
      link="base_link " />
    <child
      link="shoulder" />
    <axis
      xyz="0 1 0" />
  </joint>
  <link
    name="elbow">
    <inertial>
      <origin
        xyz="0.0156751031281576 0.02319460032387 0.141664734714677"
        rpy="0 0 0" />
      <mass
        value="0.777952609087341" />
      <inertia
        ixx="0.00228138056838171"
        ixy="6.75259187016338E-08"
        ixz="-6.02427583414272E-07"
        iyy="0.0023009303154956"
        iyz="-3.06257702544362E-05"
        izz="0.000730694022316298" />
    </inertial>
    <visual>
      <origin
        xyz="0 0 0"
        rpy="0 0 0" />
      <geometry>
        <mesh
          filename="package://urdf_v10/meshes/elbow.STL" />
      </geometry>
      <material
        name="">
        <color
          rgba="0.792156862745098 0.819607843137255 0.933333333333333 1" />
      </material>
    </visual>
    <collision>
      <origin
        xyz="0 0 0"
        rpy="0 0 0" />
      <geometry>
        <mesh
          filename="package://urdf_v10/meshes/elbow.STL" />
      </geometry>
    </collision>
  </link>
  <joint
    name="joint_3"
    type="continuous">
    <origin
      xyz="0 0 0.221123792803555"
      rpy="0 0 0" />
    <parent
      link="shoulder" />
    <child
      link="elbow" />
    <axis
      xyz="0 1 0" />
  </joint>
  <link
    name="wrist_1">
    <inertial>
      <origin
        xyz="0.0159030354177622 0.0259392011604364 0.153821393804091"
        rpy="0 0 0" />
      <mass
        value="0.336033452724337" />
      <inertia
        ixx="0.000698588486758919"
        ixy="-1.06886801077444E-06"
        ixz="4.79927277960736E-06"
        iyy="0.000573509249244474"
        iyz="1.12103478728209E-05"
        izz="0.00034880644982477" />
    </inertial>
    <visual>
      <origin
        xyz="0 0 0"
        rpy="0 0 0" />
      <geometry>
        <mesh
          filename="package://urdf_v10/meshes/wrist_1.STL" />
      </geometry>
      <material
        name="">
        <color
          rgba="0.792156862745098 0.819607843137255 0.933333333333333 1" />
      </material>
    </visual>
    <collision>
      <origin
        xyz="0 0 0"
        rpy="0 0 0" />
      <geometry>
        <mesh
          filename="package://urdf_v10/meshes/wrist_1.STL" />
      </geometry>
    </collision>
  </link>
  <joint
    name="joint_4"
    type="continuous">
    <origin
      xyz="0 0.000500999999999197 0.129539254362447"
      rpy="0 0 0" />
    <parent
      link="elbow" />
    <child
      link="wrist_1" />
    <axis
      xyz="0 0 1" />
  </joint>
  <link
    name="wrist_2">
    <inertial>
      <origin
        xyz="0.0157674862313771 0.0237812415260289 0.102441852068916"
        rpy="0 0 0" />
      <mass
        value="0.158624033379917" />
      <inertia
        ixx="8.93595815588675E-05"
        ixy="-2.61047265900904E-09"
        ixz="-6.69970075347436E-08"
        iyy="0.000106318553763209"
        iyz="-6.19881915620026E-07"
        izz="7.50977668332821E-05" />
    </inertial>
    <visual>
      <origin
        xyz="0 0 0"
        rpy="0 0 0" />
      <geometry>
        <mesh
          filename="package://urdf_v10/meshes/wrist_2.STL" />
      </geometry>
      <material
        name="">
        <color
          rgba="0.792156862745098 0.819607843137255 0.933333333333333 1" />
      </material>
    </visual>
    <collision>
      <origin
        xyz="0 0 0"
        rpy="0 0 0" />
      <geometry>
        <mesh
          filename="package://urdf_v10/meshes/wrist_2.STL" />
      </geometry>
    </collision>
  </link>
  <joint
    name="joint_5"
    type="continuous">
    <origin
      xyz="0 0 0.0989607456375549"
      rpy="0 0 0" />
    <parent
      link="wrist_1" />
    <child
      link="wrist_2" />
    <axis
      xyz="0 1 0" />
  </joint>
  <link
    name="gripper_base">
    <inertial>
      <origin
        xyz="0.0311543631130002 0.0219859947844332 0.827225405967619"
        rpy="0 0 0" />
      <mass
        value="0.0669550622887329" />
      <inertia
        ixx="2.24885106980752E-05"
        ixy="2.35779600573181E-06"
        ixz="-2.87441674024981E-06"
        iyy="3.18452559002668E-05"
        iyz="3.57683917822237E-07"
        izz="3.67649419237165E-05" />
    </inertial>
    <visual>
      <origin
        xyz="0 0 0"
        rpy="0 0 0" />
      <geometry>
        <mesh
          filename="package://urdf_v10/meshes/gripper_base.STL" />
      </geometry>
      <material
        name="">
        <color
          rgba="0.792156862745098 0.819607843137255 0.933333333333333 1" />
      </material>
    </visual>
    <collision>
      <origin
        xyz="0 0 0"
        rpy="0 0 0" />
      <geometry>
        <mesh
          filename="package://urdf_v10/meshes/gripper_base.STL" />
      </geometry>
    </collision>
  </link>
  <joint
    name="joint_6"
    type="fixed">
    <origin
      xyz="0 -0.000501000000000529 -0.666561103829396"
      rpy="0 0 0" />
    <parent
      link="wrist_2" />
    <child
      link="gripper_base" />
    <axis
      xyz="0 0 0" />
  </joint>
  <link
    name="gear1">
    <inertial>
      <origin
        xyz="0.0121731440779397 0.0223638854455627 0.106606399742784"
        rpy="0 0 0" />
      <mass
        value="0.00438273150211103" />
      <inertia
        ixx="9.8932109159113E-07"
        ixy="-2.36894708023036E-12"
        ixz="-5.18581666250675E-11"
        iyy="8.27204211795526E-07"
        iyz="-3.36050790198257E-08"
        izz="1.87956460887756E-07" />
    </inertial>
    <visual>
      <origin
        xyz="0 0 0"
        rpy="0 0 0" />
      <geometry>
        <mesh
          filename="package://urdf_v10/meshes/gear1.STL" />
      </geometry>
      <material
        name="">
        <color
          rgba="0.792156862745098 0.819607843137255 0.933333333333333 1" />
      </material>
    </visual>
    <collision>
      <origin
        xyz="0 0 0"
        rpy="0 0 0" />
      <geometry>
        <mesh
          filename="package://urdf_v10/meshes/gear1.STL" />
      </geometry>
    </collision>
  </link>
  <joint
    name="joint_7"
    type="continuous">
    <origin
      xyz="0.00342579567430223 -0.0134990000000121 0.731545773616594"
      rpy="0 0.00461853187879238 0" />
    <parent
      link="gripper_base" />
    <child
      link="gear1" />
    <axis
      xyz="0.999999997927059 0 -6.43885282803659E-05" />
  </joint>
  <link
    name="leg1-1">
    <inertial>
      <origin
        xyz="0.00929593829287573 -0.000672374283888555 0.0475923912478822"
        rpy="0 0 0" />
      <mass
        value="0.010675437516944" />
      <inertia
        ixx="4.10221567193053E-06"
        ixy="-1.70840088964406E-09"
        ixz="-9.73747876405975E-09"
        iyy="4.17675161746691E-06"
        iyz="-6.39775329162735E-07"
        izz="5.77185020661968E-07" />
    </inertial>
    <visual>
      <origin
        xyz="0 0 0"
        rpy="0 0 0" />
      <geometry>
        <mesh
          filename="package://urdf_v10/meshes/leg1-1.STL" />
      </geometry>
      <material
        name="">
        <color
          rgba="0.792156862745098 0.819607843137255 0.933333333333333 1" />
      </material>
    </visual>
    <collision>
      <origin
        xyz="0 0 0"
        rpy="0 0 0" />
      <geometry>
        <mesh
          filename="package://urdf_v10/meshes/leg1-1.STL" />
      </geometry>
    </collision>
  </link>
  <joint
    name="joint_11"
    type="fixed">
    <origin
      xyz="0.0031365 0.030395 0.11869"
      rpy="0 -0.0046185 0" />
    <parent
      link="gear1" />
    <child
      link="leg1-1" />
    <axis
      xyz="0 0 0" />
  </joint>
  <link
    name="gear2">
    <inertial>
      <origin
        xyz="0.0126653808977272 0.0244269735564364 0.106549040913118"
        rpy="0 0 0" />
      <mass
        value="0.00438273150125593" />
      <inertia
        ixx="9.89303521070554E-07"
        ixy="1.57163638382398E-10"
        ixz="-3.75240983571211E-09"
        iyy="8.27204209950204E-07"
        iyz="3.3604703827397E-08"
        izz="1.87974027803604E-07" />
    </inertial>
    <visual>
      <origin
        xyz="0 0 0"
        rpy="0 0 0" />
      <geometry>
        <mesh
          filename="package://urdf_v10/meshes/gear2.STL" />
      </geometry>
      <material
        name="">
        <color
          rgba="0.792156862745098 0.819607843137255 0.933333333333333 1" />
      </material>
    </visual>
    <collision>
      <origin
        xyz="0 0 0"
        rpy="0 0 0" />
      <geometry>
        <mesh
          filename="package://urdf_v10/meshes/gear2.STL" />
      </geometry>
    </collision>
  </link>
  <joint
    name="joint_8"
    type="continuous">
    <origin
      xyz="0.0034258 0.014501 0.73155"
      rpy="0 0 0" />
    <parent
      link="gripper_base" />
    <child
      link="gear2" />
    <axis
      xyz="-0.99999 0 0.0046829" />
    <mimic
      joint="joint_7"
      multiplier="-1"
      offset="0" />
  </joint>
  <link
    name="leg2-1">
    <inertial>
      <origin
        xyz="-9.84910035084496E-05 -0.0497032278500568 0.76462584713727"
        rpy="0 0 0" />
      <mass
        value="0.0106754461770056" />
      <inertia
        ixx="4.10221667015722E-06"
        ixy="-1.70826774116559E-09"
        ixz="-9.73784470888698E-09"
        iyy="4.17675215863977E-06"
        iyz="-6.39775026489062E-07"
        izz="5.77185107952777E-07" />
    </inertial>
    <visual>
      <origin
        xyz="0 0 0"
        rpy="0 0 0" />
      <geometry>
        <mesh
          filename="package://urdf_v10/meshes/leg2-1.STL" />
      </geometry>
      <material
        name="">
        <color
          rgba="0.792156862745098 0.819607843137255 0.933333333333333 1" />
      </material>
    </visual>
    <collision>
      <origin
        xyz="0 0 0"
        rpy="0 0 0" />
      <geometry>
        <mesh
          filename="package://urdf_v10/meshes/leg2-1.STL" />
      </geometry>
    </collision>
  </link>
  <joint
    name="joint_12"
    type="fixed">
    <origin
      xyz="0.0056497 -0.032635 -0.59833"
      rpy="0 -0.0093658 3.1416" />
    <parent
      link="gear2" />
    <child
      link="leg2-1" />
    <axis
      xyz="0.99999 0 -0.0046829" />
  </joint>
  <link
    name="parm1">
    <inertial>
      <origin
        xyz="0.0121739234023694 0.0231204445028104 0.118683662009147"
        rpy="0 0 0" />
      <mass
        value="0.00163735500294608" />
      <inertia
        ixx="3.04623075919876E-07"
        ixy="2.60134978223588E-13"
        ixz="-1.89774342401843E-11"
        iyy="3.03667099460086E-07"
        iyz="4.03369978526193E-09"
        izz="1.03540953234062E-08" />
    </inertial>
    <visual>
      <origin
        xyz="0 0 0"
        rpy="0 0 0" />
      <geometry>
        <mesh
          filename="package://urdf_v10/meshes/parm1.STL" />
      </geometry>
      <material
        name="">
        <color
          rgba="0.792156862745098 0.819607843137255 0.933333333333333 1" />
      </material>
    </visual>
    <collision>
      <origin
        xyz="0 0 0"
        rpy="0 0 0" />
      <geometry>
        <mesh
          filename="package://urdf_v10/meshes/parm1.STL" />
      </geometry>
    </collision>
  </link>
  <joint
    name="joint_9"
    type="continuous">
    <origin
      xyz="0.00351945374055956 -0.00649900000001213 0.751545554409805"
      rpy="0 0.00461853180586022 0" />
    <parent
      link="gripper_base" />
    <child
      link="parm1" />
    <axis
      xyz="0.999999997927054 0 -6.4388601212528E-05" />
    <mimic
      joint="joint_7"
      multiplier="1"
      offset="0" />
  </joint>
  <link
    name="parm_2">
    <inertial>
      <origin
        xyz="0.0121739233969216 0.0236704345270295 0.118683661755409"
        rpy="0 0 0" />
      <mass
        value="0.001637355002946" />
      <inertia
        ixx="3.04623075919875E-07"
        ixy="-2.6018916526957E-13"
        ixz="-1.89774192851861E-11"
        iyy="3.0366707623103E-07"
        iyz="-4.03454425436892E-09"
        izz="1.03541185524565E-08" />
    </inertial>
    <visual>
      <origin
        xyz="0 0 0"
        rpy="0 0 0" />
      <geometry>
        <mesh
          filename="package://urdf_v10/meshes/parm_2.STL" />
      </geometry>
      <material
        name="">
        <color
          rgba="0.792156862745098 0.819607843137255 0.933333333333333 1" />
      </material>
    </visual>
    <collision>
      <origin
        xyz="0 0 0"
        rpy="0 0 0" />
      <geometry>
        <mesh
          filename="package://urdf_v10/meshes/parm_2.STL" />
      </geometry>
    </collision>
  </link>
  <joint
    name="joint_10"
    type="continuous">
    <origin
      xyz="0.00351945374057844 0.00750099999998788 0.751545554409805"
      rpy="0 0.00461853185163578 0" />
    <parent
      link="gripper_base" />
    <child
      link="parm_2" />
    <axis
      xyz="0.999999997927057 0 -6.43885554369675E-05" />
    <mimic
      joint="joint_9"
      multiplier="-1"
      offset="0" />
  </joint>
</robot>
