<?xml version="1.0" encoding="utf-8" ?>
<!-- This URDF was automatically created by SolidWorks to URDF Exporter! Originally created by Stephen Brawner (brawner@gmail.com) 
     Commit Version: 1.6.0-4-g7f85cfe  Build Version: 1.6.7995.38578
     For more information, please see http://wiki.ros.org/sw_urdf_exporter -->
<robot name="urdf_v12">
    <link name="base">
        <inertial>
            <origin xyz="-0.0277896697354432 0.0234076824741036 0.0288009133480316" rpy="0 0 0" />
            <mass value="1.8044550393165" />
            <inertia ixx="0.00557261131338954" ixy="1.30566237539955E-06" ixz="-0.000539475236705643" iyy="0.0133501948742322" iyz="4.50573002158927E-07" izz="0.0165394809245894" />
        </inertial>
        <visual>
            <origin xyz="0 0 0" rpy="0 0 0" />
            <geometry>
                <mesh filename="package://urdf_v12/meshes/base.STL" />
            </geometry>
            <material name="">
                <color rgba="0.792156862745098 0.819607843137255 0.933333333333333 1" />
            </material>
        </visual>
        <collision>
            <origin xyz="0 0 0" rpy="0 0 0" />
            <geometry>
                <mesh filename="package://urdf_v12/meshes/base.STL" />
            </geometry>
        </collision>
    </link>
    <link name="base_link ">
        <inertial>
            <origin xyz="0.0157132867710385 0.0115275527781427 0.181315179513602" rpy="0 0 0" />
            <mass value="2.09089508032489" />
            <inertia ixx="0.0136133861667005" ixy="4.81773432935839E-06" ixz="-8.58975697793193E-06" iyy="0.00966545437205446" iyz="-0.000408881289535838" izz="0.00889732683732312" />
        </inertial>
        <visual>
            <origin xyz="0 0 0" rpy="0 0 0" />
            <geometry>
                <mesh filename="package://urdf_v12/meshes/base_link .STL" />
            </geometry>
            <material name="">
                <color rgba="0.792156862745098 0.819607843137255 0.933333333333333 1" />
            </material>
        </visual>
        <collision>
            <origin xyz="0 0 0" rpy="0 0 0" />
            <geometry>
                <mesh filename="package://urdf_v12/meshes/base_link .STL" />
            </geometry>
        </collision>
    </link>
    <joint name="joint_1" type="continuous">
        <origin xyz="0 0 -0.0180509566114611" rpy="0 0 0" />
        <parent link="base" />
        <child link="base_link " />
        <axis xyz="0 0 1" />
    </joint>
    <link name="shoulder">
        <inertial>
            <origin xyz="0.0158644325462804 0.02504162834465 0.178555302511376" rpy="0 0 0" />
            <mass value="1.93113192422205" />
            <inertia ixx="0.0170862699436261" ixy="3.41462705541798E-06" ixz="-5.32114229637754E-07" iyy="0.0162697572588696" iyz="-0.00012309676700551" izz="0.00359988404935739" />
        </inertial>
        <visual>
            <origin xyz="0 0 0" rpy="0 0 0" />
            <geometry>
                <mesh filename="package://urdf_v12/meshes/shoulder.STL" />
            </geometry>
            <material name="">
                <color rgba="0.792156862745098 0.819607843137255 0.933333333333333 1" />
            </material>
        </visual>
        <collision>
            <origin xyz="0 0 0" rpy="0 0 0" />
            <geometry>
                <mesh filename="package://urdf_v12/meshes/shoulder.STL" />
            </geometry>
        </collision>
    </link>
    <joint name="joint_2" type="continuous">
        <origin xyz="0 0 0.166937311025839" rpy="0 0 0" />
        <parent link="base_link " />
        <child link="shoulder" />
        <axis xyz="0 1 0" />
    </joint>
    <link name="elbow">
        <inertial>
            <origin xyz="0.0156751030974169 0.023194600323863 0.141664728150207" rpy="0 0 0" />
            <mass value="0.777952609087341" />
            <inertia ixx="0.00228138056838172" ixy="6.75259187042004E-08" ixz="-6.02427583403919E-07" iyy="0.0023009303154956" iyz="-3.06257702544412E-05" izz="0.000730694022316298" />
        </inertial>
        <visual>
            <origin xyz="0 0 0" rpy="0 0 0" />
            <geometry>
                <mesh filename="package://urdf_v12/meshes/elbow.STL" />
            </geometry>
            <material name="">
                <color rgba="0.792156862745098 0.819607843137255 0.933333333333333 1" />
            </material>
        </visual>
        <collision>
            <origin xyz="0 0 0" rpy="0 0 0" />
            <geometry>
                <mesh filename="package://urdf_v12/meshes/elbow.STL" />
            </geometry>
        </collision>
    </link>
    <joint name="joint_3" type="continuous">
        <origin xyz="0 0 0.221123792803555" rpy="0 0 0" />
        <parent link="shoulder" />
        <child link="elbow" />
        <axis xyz="0 1 0" />
    </joint>
    <link name="wrist_1">
        <inertial>
            <origin xyz="0.0159030353870169 0.0259392011604309 0.153821387239627" rpy="0 0 0" />
            <mass value="0.336033452724272" />
            <inertia ixx="0.00069858848675879" ixy="-1.06886801076148E-06" ixz="4.79927277955125E-06" iyy="0.00057350924924435" iyz="1.12103478728337E-05" izz="0.000348806449824697" />
        </inertial>
        <visual>
            <origin xyz="0 0 0" rpy="0 0 0" />
            <geometry>
                <mesh filename="package://urdf_v12/meshes/wrist_1.STL" />
            </geometry>
            <material name="">
                <color rgba="0.792156862745098 0.819607843137255 0.933333333333333 1" />
            </material>
        </visual>
        <collision>
            <origin xyz="0 0 0" rpy="0 0 0" />
            <geometry>
                <mesh filename="package://urdf_v12/meshes/wrist_1.STL" />
            </geometry>
        </collision>
    </link>
    <joint name="joint_4" type="continuous">
        <origin xyz="0 0.000500999999999197 0.129539254362447" rpy="0 0 0" />
        <parent link="elbow" />
        <child link="wrist_1" />
        <axis xyz="0 0 1" />
    </joint>
    <link name="wrist_2">
        <inertial>
            <origin xyz="0.0157674794651573 0.0237812416320284 0.102441846080264" rpy="0 0 0" />
            <mass value="0.158623990065244" />
            <inertia ixx="8.93595776003998E-05" ixy="-2.61088693015929E-09" ixz="-6.69993158028924E-08" iyy="0.000106318527143667" iyz="-6.1988188063972E-07" izz="7.50977341794514E-05" />
        </inertial>
        <visual>
            <origin xyz="0 0 0" rpy="0 0 0" />
            <geometry>
                <mesh filename="package://urdf_v12/meshes/wrist_2.STL" />
            </geometry>
            <material name="">
                <color rgba="0.792156862745098 0.819607843137255 0.933333333333333 1" />
            </material>
        </visual>
        <collision>
            <origin xyz="0 0 0" rpy="0 0 0" />
            <geometry>
                <mesh filename="package://urdf_v12/meshes/wrist_2.STL" />
            </geometry>
        </collision>
    </link>
    <joint name="joint_5" type="continuous">
        <origin xyz="0 0 0.0989607456375549" rpy="0 0 0" />
        <parent link="wrist_1" />
        <child link="wrist_2" />
        <axis xyz="0 1 0" />
    </joint>
    <link name="gripper_base">
        <inertial>
            <origin xyz="0.0311543630683594 0.0219859939784245 0.827225396554336" rpy="0 0 0" />
            <mass value="0.0669550622965298" />
            <inertia ixx="2.24885107007778E-05" ixy="2.35779600503439E-06" ixz="-2.87441674031664E-06" iyy="3.18452559005093E-05" iyz="3.5768391759538E-07" izz="3.67649419265546E-05" />
        </inertial>
        <visual>
            <origin xyz="0 0 0" rpy="0 0 0" />
            <geometry>
                <mesh filename="package://urdf_v12/meshes/gripper_base.STL" />
            </geometry>
            <material name="">
                <color rgba="0.792156862745098 0.819607843137255 0.933333333333333 1" />
            </material>
        </visual>
        <collision>
            <origin xyz="0 0 0" rpy="0 0 0" />
            <geometry>
                <mesh filename="package://urdf_v12/meshes/gripper_base.STL" />
            </geometry>
        </collision>
    </link>
    <joint name="joint_6" type="fixed">
        <origin xyz="0 -0.000501000000000529 -0.666561103829396" rpy="0 0 0" />
        <parent link="wrist_2" />
        <child link="gripper_base" />
        <axis xyz="0 0 0" />
    </joint>
    <link name="gear1">
        <inertial>
            <origin xyz="0.00313198682169658 -0.00793428732007617 -0.000937213624747468" rpy="0 0 0" />
            <mass value="0.00438273150212106" />
            <inertia ixx="9.89317514922847E-07" ixy="1.98723010737954E-10" ixz="-7.64271136153673E-10" iyy="1.89001348619673E-07" iyz="4.23805891108935E-08" izz="8.26162900732732E-07" />
        </inertial>
        <visual>
            <origin xyz="0 0 0" rpy="0 0 0" />
            <geometry>
                <mesh filename="package://urdf_v12/meshes/gear1.STL" />
            </geometry>
            <material name="">
                <color rgba="0.792156862745098 0.819607843137255 0.933333333333333 1" />
            </material>
        </visual>
        <collision>
            <origin xyz="0 0 0" rpy="0 0 0" />
            <geometry>
                <mesh filename="package://urdf_v12/meshes/gear1.STL" />
            </geometry>
        </collision>
    </link>
    <joint name="joint_7" type="continuous">
        <origin xyz="0.012918 0.0098964 0.83019" rpy="-1.557 0.0046185 0.0046825" />
        <parent link="gripper_base" />
        <child link="gear1" />
        <axis xyz="0.99999 0 -0.0046829" />
    </joint>
    <link name="leg1-1">
        <inertial>
            <origin xyz="0.00929593828673914 -0.000672396815212528 0.0475923899361654" rpy="0 0 0" />
            <mass value="0.0106754375171176" />
            <inertia ixx="4.10221567194114E-06" ixy="-1.70838921651009E-09" ixz="-9.73748421490424E-09" iyy="4.17675309849148E-06" iyz="-6.39771162927071E-07" izz="5.77183539710656E-07" />
        </inertial>
        <visual>
            <origin xyz="0 0 0" rpy="0 0 0" />
            <geometry>
                <mesh filename="package://urdf_v12/meshes/leg1-1.STL" />
            </geometry>
            <material name="">
                <color rgba="0.792156862745098 0.819607843137255 0.933333333333333 1" />
            </material>
        </visual>
        <collision>
            <origin xyz="0 0 0" rpy="0 0 0" />
            <geometry>
                <mesh filename="package://urdf_v12/meshes/leg1-1.STL" />
            </geometry>
        </collision>
    </link>
    <joint name="joint_11" type="fixed">
        <origin xyz="-0.0058669 -0.019902 0.0073019" rpy="1.557 0.0046185 -0.0046825" />
        <parent link="gear1" />
        <child link="leg1-1" />
        <axis xyz="0 0 0" />
    </joint>
    <link name="gear2">
        <inertial>
            <origin xyz="-0.00318902659387393 -0.00793428571902788 -0.000907612629209242" rpy="0 0 0" />
            <mass value="0.0043827315012652" />
            <inertia ixx="9.89317512179051E-07" ixy="1.98725634078648E-10" ixz="-7.64271668328125E-10" iyy="1.89001348302896E-07" iyz="4.23805870596426E-08" izz="8.26162898343221E-07" />
        </inertial>
        <visual>
            <origin xyz="0 0 0" rpy="0 0 0" />
            <geometry>
                <mesh filename="package://urdf_v12/meshes/gear2.STL" />
            </geometry>
            <material name="">
                <color rgba="0.792156862745098 0.819607843137255 0.933333333333333 1" />
            </material>
        </visual>
        <collision>
            <origin xyz="0 0 0" rpy="0 0 0" />
            <geometry>
                <mesh filename="package://urdf_v12/meshes/gear2.STL" />
            </geometry>
        </collision>
    </link>
    <joint name="joint_8" type="continuous">
        <origin xyz="0.012869 0.037896 0.83019" rpy="-1.5571 -0.0047473 -3.1369" />
        <parent link="gripper_base" />
        <child link="gear2" />
        <axis xyz="0.99999 0 -0.0046829" />
        <mimic joint="joint_7" multiplier="1" offset="0" />
    </joint>
    <link name="leg2-1">
        <inertial>
            <origin xyz="-9.8491060829542E-05 -0.0497032246791672 0.76462583489705" rpy="0 0 0" />
            <mass value="0.0106754461770065" />
            <inertia ixx="4.10221667015741E-06" ixy="-1.70826774117383E-09" ixz="-9.73784470875661E-09" iyy="4.17675215864E-06" iyz="-6.39775026489047E-07" izz="5.77185107952822E-07" />
        </inertial>
        <visual>
            <origin xyz="0 0 0" rpy="0 0 0" />
            <geometry>
                <mesh filename="package://urdf_v12/meshes/leg2-1.STL" />
            </geometry>
            <material name="">
                <color rgba="0.792156862745098 0.819607843137255 0.933333333333333 1" />
            </material>
        </visual>
        <collision>
            <origin xyz="0 0 0" rpy="0 0 0" />
            <geometry>
                <mesh filename="package://urdf_v12/meshes/leg2-1.STL" />
            </geometry>
        </collision>
    </link>
    <joint name="joint_12" type="fixed">
        <origin xyz="0.00074747 0.69769 0.046439" rpy="1.557 0.0046185 -0.0046825" />
        <parent link="gear2" />
        <child link="leg2-1" />
        <axis xyz="0 0 0" />
    </joint>
    <transmission name="trans_joint_1">
        <type>transmission_interface/SimpleTransmission</type>
        <joint name="joint_1">
            <hardwareInterface>hardware_interface/EffortJointInterface</hardwareInterface>
        </joint>
        <actuator name="joint_1_motor">
            <hardwareInterface>hardware_interface/EffortJointInterface</hardwareInterface>
            <mechanicalReduction>1</mechanicalReduction>
        </actuator>
    </transmission>
    <transmission name="trans_joint_2">
        <type>transmission_interface/SimpleTransmission</type>
        <joint name="joint_2">
            <hardwareInterface>hardware_interface/EffortJointInterface</hardwareInterface>
        </joint>
        <actuator name="joint_2_motor">
            <hardwareInterface>hardware_interface/EffortJointInterface</hardwareInterface>
            <mechanicalReduction>1</mechanicalReduction>
        </actuator>
    </transmission>
    <transmission name="trans_joint_3">
        <type>transmission_interface/SimpleTransmission</type>
        <joint name="joint_3">
            <hardwareInterface>hardware_interface/EffortJointInterface</hardwareInterface>
        </joint>
        <actuator name="joint_3_motor">
            <hardwareInterface>hardware_interface/EffortJointInterface</hardwareInterface>
            <mechanicalReduction>1</mechanicalReduction>
        </actuator>
    </transmission>
    <transmission name="trans_joint_4">
        <type>transmission_interface/SimpleTransmission</type>
        <joint name="joint_4">
            <hardwareInterface>hardware_interface/EffortJointInterface</hardwareInterface>
        </joint>
        <actuator name="joint_4_motor">
            <hardwareInterface>hardware_interface/EffortJointInterface</hardwareInterface>
            <mechanicalReduction>1</mechanicalReduction>
        </actuator>
    </transmission>
    <transmission name="trans_joint_5">
        <type>transmission_interface/SimpleTransmission</type>
        <joint name="joint_5">
            <hardwareInterface>hardware_interface/EffortJointInterface</hardwareInterface>
        </joint>
        <actuator name="joint_5_motor">
            <hardwareInterface>hardware_interface/EffortJointInterface</hardwareInterface>
            <mechanicalReduction>1</mechanicalReduction>
        </actuator>
    </transmission>
    <transmission name="trans_joint_7">
        <type>transmission_interface/SimpleTransmission</type>
        <joint name="joint_7">
            <hardwareInterface>hardware_interface/EffortJointInterface</hardwareInterface>
        </joint>
        <actuator name="joint_7_motor">
            <hardwareInterface>hardware_interface/EffortJointInterface</hardwareInterface>
            <mechanicalReduction>1</mechanicalReduction>
        </actuator>
    </transmission>
    <transmission name="trans_joint_8">
        <type>transmission_interface/SimpleTransmission</type>
        <joint name="joint_8">
            <hardwareInterface>hardware_interface/EffortJointInterface</hardwareInterface>
        </joint>
        <actuator name="joint_8_motor">
            <hardwareInterface>hardware_interface/EffortJointInterface</hardwareInterface>
            <mechanicalReduction>1</mechanicalReduction>
        </actuator>
    </transmission>
    <gazebo>
        <plugin name="gazebo_ros_control">
            <robotNamespace>/</robotNamespace>
        </plugin>
    </gazebo>
</robot>

